20200831164855
Traceback (most recent call last):
  File "/home/aitra/.local/lib/python3.8/site-packages/serial/serialposix.py", line 500, in read
    raise SerialException(
serial.serialutil.SerialException: device reports readiness to read but returned no data (device disconnected or multiple access on port?)

During handling of the above exception, another exception occurred:

Traceback (most recent call last):
  File "/home/aitra/Documents/ait_exp/tada/tada_main.py", line 43, in <module>
    ui.mainloop()
  File "/home/aitra/Documents/ait_exp/tada/src/tada_ui.py", line 75, in mainloop
    self.daq_loop()
  File "/home/aitra/Documents/ait_exp/tada/src/tada_ui.py", line 92, in daq_loop
    data_point += src.get_data()
  File "/home/aitra/Documents/ait_exp/tada/src/data_src.py", line 128, in get_data
    data_string = self.ser.readline().decode()
  File "/home/aitra/.local/lib/python3.8/site-packages/serial/serialposix.py", line 509, in read
    raise SerialException('read failed: {}'.format(e))
serial.serialutil.SerialException: read failed: device reports readiness to read but returned no data (device disconnected or multiple access on port?)
